Workbook

Sheet DCF (2)
B1: Pepsico DCF Valuation
B2: (in USD million except per Share Data)
B3: Valuation Date | C3: 45138
B4: Latest Filing | C4: 45094
B5: Choose Discounting | C5: =IF(D5=A59,B59,B60) -> Year end discounting | D5: 2
C7: 6 | D7: 12 | E7: 12 | F7: 12 | G7: 12
B8: Date of cash flows | C8: Dec. 31, 2023 | D8: Dec. 31, 2024 | E8: Dec. 31, 2025 | F8: Dec. 31, 2026 | G8: Dec. 31, 2027
B10: EBIT | C10: ='PepsiCo-IS'!G22 -> 9563.1158 | D10: ='PepsiCo-IS'!I22 -> 15658.592 | E10: ='PepsiCo-IS'!J22 -> 16976.878 | F10: ='PepsiCo-IS'!K22 -> 18409.165 | G10: ='PepsiCo-IS'!L22 -> 19965.757
B11: Tax Rate | C11: ='PepsiCo-IS'!G59 -> 0.21645768 | D11: ='PepsiCo-IS'!I59 -> 0.21975928 | E11: ='PepsiCo-IS'!J59 -> 0.23566586 | F11: ='PepsiCo-IS'!K59 -> 0.25157243 | G11: ='PepsiCo-IS'!L59 -> 0.26747901
B12: NOPAT | C12: =C10*(1-C11) -> 7493.1059 | D12: =D10*(1-D11) -> 12217.471 | E12: =E10*(1-E11) -> 12976.007 | F12: =F10*(1-F11) -> 13777.926 | G12: =G10*(1-G11) -> 14625.336
B13: Add: Depreciation and amortisation | C13: ='Pepsico-CFS'!B8 -> 1655.908 | D13: ='Pepsico-CFS'!C8 -> 3580.5256 | E13: ='Pepsico-CFS'!D8 -> 3870.9446 | F13: ='Pepsico-CFS'!E8 -> 4187.0864 | G13: ='Pepsico-CFS'!F8 -> 4531.2419
B14: Add/Less: (Increase)/ Decrease in net working capital | C14: =SUM('Pepsico-CFS'!B11:B14) -> 4638.9017 | D14: =SUM('Pepsico-CFS'!C11:C14) -> 916.44749 | E14: =SUM('Pepsico-CFS'!D11:D14) -> 757.59314 | F14: =SUM('Pepsico-CFS'!E11:E14) -> 823.39412 | G14: =SUM('Pepsico-CFS'!F11:F14) -> 895.12621
B15: Less: Capital expenditure | C15: ='Pepsico-CFS'!B19 -> -6708.4559 | D15: ='Pepsico-CFS'!C19 -> -4224.2602 | E15: ='Pepsico-CFS'!D19 -> -6342.5553 | F15: ='Pepsico-CFS'!E19 -> -6882.0533 | G15: ='Pepsico-CFS'!F19 -> -7469.2155
B16: Debt free cash flow (Free Cash Flows to Firm) | C16: =C12+C13+C15+C14 -> 7079.4598 | D16: =D12+D13+D15+D14 -> 12490.184 | E16: =E12+E13+E15+E14 -> 11261.99 | F16: =F12+F13+F15+F14 -> 11906.354 | G16: =G12+G13+G15+G14 -> 12582.489
A17: =WACC!N8 -> 0.066785734 | B17: Discount rate (%) | C17: =C16*$A$17 -> 472.80692 | D17: =D16*$A$17 -> 834.16612 | E17: =E16*$A$17 -> 752.14025 | F17: =F16*$A$17 -> 795.17457 | G17: =G16*$A$17 -> 840.33076
B18: Discounting Period-Year End | C18: 0.5 | D18: =C18+1 -> 1.5 | E18: =D18+1 -> 2.5 | F18: =E18+1 -> 3.5 | G18: =F18+1 -> 4.5
B19: Discounting Period-Mid Year | C19: =0.25 -> 0.25 | D19: 1 | E19: =D19+1 -> 2 | F19: =E19+1 -> 3 | G19: =F19+1 -> 4
B20: Present value factor- Year end discounting | C20: =1/(1+$A$17)^C18 -> 0.9681918 | D20: =1/(1+$A$17)^D18 -> 0.9075785 | E20: =1/(1+$A$17)^E18 -> 0.85075988 | F20: =1/(1+$A$17)^F18 -> 0.79749837 | G20: =1/(1+$A$17)^G18 -> 0.74757127 | I20: this is done using the formula of fv, when wacc is given
B21: Present value factor- Mid year discounting | C21: =1/(1+$A$17)^C19 -> 0.98396738 | D21: =1/(1+$A$17)^D19 -> 0.93739536 | E21: =1/(1+$A$17)^E19 -> 0.87871007 | F21: =1/(1+$A$17)^F19 -> 0.82369874 | G21: =1/(1+$A$17)^G19 -> 0.77213138
B22: Present value debt free cash flow | C22: =CHOOSE($D$5,C21,C20)*C16 -> 6854.2749 | D22: =CHOOSE($D$5,D21,D20)*D16 -> 11335.823 | E22: =CHOOSE($D$5,E21,E20)*E16 -> 9581.249 | F22: =CHOOSE($D$5,F21,F20)*F16 -> 9495.2975 | G22: =CHOOSE($D$5,G21,G20)*G16 -> 9406.3071 | I22: =CHOOSE($D$5,C21,C20)*C16 -> 6854.2749 | J22: =CHOOSE($D$5,D21,D20)*D16 -> 11335.823 | K22: =CHOOSE($D$5,E21,E20)*E16 -> 9581.249 | L22: =CHOOSE($D$5,F21,F20)*F16 -> 9495.2975 | M22: =CHOOSE($D$5,G21,G20)*G16 -> 9406.3071 | N22: =CHOOSE($D$5,H21,H20)*H16 -> 0 | O22: =CHOOSE($D$5,I21,I20)*I16 -> #VALUE!
B24: Present value for explicit period | C24: =SUM(C22:G22) -> 46672.951
J25: WACC
B26: Terminal value | D26: Gordon growth | I26: =D38 -> 157.98255 | J26: 0.0575 | K26: =J26+0.25% -> 0.06 | L26: =K26+0.25% -> 0.0625 | M26: =L26+0.25% -> 0.065 | N26: =M26+0.25% -> 0.0675 | O26: =N26+0.25% -> 0.07 | P26: =O26+0.25% -> 0.0725 | Q26: =P26+0.25% -> 0.075 | R26: =Q26+0.25% -> 0.0775
B27: Long Term Growth Rate | D27: 0.02 | H27: LTGR | I27: 0.01 | J27: 160.90666 | K27: 151.62214 | L27: 143.22253 | M27: 135.58714 | N27: 128.61629 | O27: 122.22689 | P27: 116.34918 | Q27: 110.9241 | R27: 105.90135
B28: Terminal Value | D28: =G16*(1+D27)/(A17-D27) -> 274317.35 | F28: FCFF/WACC-g | I28: =I27+0.25% -> 0.0125 | J28: 169.69724 | K28: 159.46855 | L28: 150.26337 | M28: 141.93547 | N28: 134.36521 | O28: 127.45378 | P28: 121.11879 | Q28: 115.29109 | R28: 109.91212
B29: Present Value of TV | D29: =D28*CHOOSE(D5,G21,G20) -> 205071.77 | F29: multiplied by discounting factor | I29: =I28+0.25% -> 0.015 | J29: 179.522 | K29: 168.18678 | L29: 158.04535 | M29: 148.91863 | N29: 140.66166 | O29: 133.15583 | P29: 126.30315 | Q29: 120.02199 | R29: 114.24374
B30: DCF Value of Firm / Operating Business Enterprise Value | D30: =C24+D29 -> 251744.72 | I30: =I29+0.25% -> 0.0175 | J30: 190.57486 | K30: 177.93068 | L30: 166.69199 | M30: 156.63686 | N30: 147.58775 | O30: 139.40093 | P30: 131.95882 | Q30: 125.16427 | R30: 118.93634
B31: Add: Non Operating Assets | D31: ='PepsiCo-BS'!F6+'PepsiCo-BS'!F17 -> 3376 | I31: =I30+0.25% -> 0.02 | J31: 203.10144 | K31: 188.89257 | L31: 176.35588 | M31: 165.21267 | N31: 155.2429 | O31: 146.27055 | P31: 138.15312 | Q31: 130.77404 | R31: 124.03699
B32: Total Value of Firm | D32: =D30+D31 -> 255120.72 | I32: =I31+0.25% -> 0.0225 | J32: 217.41752 | K32: 201.31605 | L32: 187.22776 | M32: 174.7974 | N32: 163.74862 | O32: 153.86328 | P32: 144.96685 | Q32: 136.91807 | R32: 129.60133
B33: Less: Gross Debt & Debt Equivalents | D33: ='PepsiCo-BS'!F23+'PepsiCo-BS'!F28 -> 43621 | I33: =I32+0.25% -> 0.025 | J33: 233.93608 | K33: 215.5143 | L33: 199.54923 | M33: 185.58022 | N33: 173.25501 | O33: 162.29965 | P33: 152.49782 | Q33: 143.6765 | R33: 135.69561
B34: Add: Cash | D34: ='PepsiCo-BS'!F5 -> 6116 | I34: =I33+0.25% -> 0.0275 | J34: 253.20773 | K34: 231.89691 | L34: 213.6309 | M34: 197.80075 | N34: 183.94971 | O34: 171.72853 | P34: 160.86556 | Q34: 151.14635 | R34: 142.39932
B35: Less: Non Controling Interest | D35: ='PepsiCo-BS'!F39 -> 140 | I35: =I34+0.25% -> 0.03 | J35: 275.98333 | K35: 251.00995 | L35: 229.87899 | M35: 211.76707 | N35: 196.07036 | O35: 182.33602 | P35: 170.21774 | Q35: 159.44618 | R35: 149.80868
B36: DCF value of Common Equity | D36: =D32-D33+D34-D35 -> 217475.72
B37: No. of shares o/s | D37: =WACC!E38 -> 1376.5806
B38: DCF value per share | D38: =D36/D37 -> 157.98255
J39: WACC
B40: Terminal Value | D40: Exit Multiple Method | E40: from this we can find the values directly | I40: =D53 -> 188.00843 | J40: =J26 -> 0.0575 | K40: =K26 -> 0.06 | L40: =L26 -> 0.0625 | M40: =M26 -> 0.065 | N40: =N26 -> 0.0675 | O40: =O26 -> 0.07 | P40: =P26 -> 0.0725 | Q40: =Q26 -> 0.075 | R40: =R26 -> 0.0775
B41: LTM EV/EBITDA | D41: =(16.9+10.01)/2 -> 13.455 | E41: us industry based multiples+damodaran | H41: Exit Multiple | I41: 12.5 | J41: 182.74904 | K41: 180.70996 | L41: 178.69656 | M41: 176.70846 | N41: 174.74528 | O41: 172.80665 | P41: 170.8922 | Q41: 169.00158 | R41: 167.13442
B42: Terminal Year EBITDA | D42: =G10+G13 -> 24496.999 | E42: ebit+dep is ebidta | I42: =I41+1 -> 13.5 | J42: 196.58628 | K42: 194.40095 | L42: 192.24318 | M42: 190.11257 | N42: 188.00871 | O42: 185.9312 | P42: 183.87964 | Q42: 181.85365 | R42: 179.85285
B43: Terminal Value | D43: =D41*D42 -> 329607.12 | I43: =I42+1 -> 14.5 | J43: 210.42353 | K43: 208.09194 | L43: 205.7898 | M43: 203.51668 | N43: 201.27214 | O43: 199.05574 | P43: 196.86707 | Q43: 194.70572 | R43: 192.57128
...

Sheet WACC
B1: PepsiCo WACC Calculation
B2: (in USD million except per Share Data)
C3: 1 | D3: =IF(C3=A24,B24,B25) -> Bottoms Up beta
B4: Cost of equity | F4: Cost of debt | J4: Weighted average cost of capital
B5: Particulars | C5: Notes | D5: Value | F5: Particulars | G5: Notes | H5: Value | J5: Particulars | K5: Weight | L5: Particulars | M5: Cost | N5: Value
B6: Risk-free rate (%) | C6: 10-year treasury rate | D6: 0.0397 | F6: Debt borrowing rate (%) | G6: Ratings Based | H6: =D6+0.7% -> 0.0467 | J6: Debt (%) | K6: =D25 -> 0.15108108 | L6: Cost of debt (%) | M6: =H8 -> 0.034091 | N6: =M6*K6 -> 0.0051505052 | S6: S&P 500
B7: Beta | C7: =D3 -> Bottoms Up beta | D7: =CHOOSE(C3,H22,H25) -> 0.73120838 | F7: Expected income tax rate (%) | H7: 0.27 | J7: Equity (%) | K7: =1-K6 -> 0.84891892 | L7: Cost of equity (%) | M7: =D9 -> 0.072604377 | N7: =M7*K7 -> 0.061635229
B8: Equity market risk premium (%) | C8: Damodaram ERP | D8: =4.5% -> 0.045 | F8: After-tax cost of debt (%) | H8: =H6*(1-H7) -> 0.034091 | J8: WACC | N8: =SUM(N6:N7) -> 0.066785734 | S8: Initial date | U8: 57.57 | V8: 22284
B9: Cost of equity capital (%) | D9: =D6+D7*D8 -> 0.072604377 | S9: End date | U9: 7431.6 | V9: 46188
C11: from erp predictive model- damodaram site | S11: time | V11: =YEARFRAC(V8,V9,1) -> 65.446943
S12: CAGR | V12: =RATE(V11,0,-U8,U9,0) -> 0.077093475
B13: Calculation of beta
B14: Particulars | C14: Levered beta | D14: D/(D+E) (last three years) | E14: E/(D+E) (last three years) | F14: Tax rate (%) | G14: Unlevered beta | H14: Relevered beta | S14: ERP | V14: =V12-D6 -> 0.037393475
B15: Bottom-up
B16: =[1]Beta!D6 -> Coca Cola | C16: =Beta!E6 -> 0.81092836 | D16: =AVERAGE(C33:C35)/(AVERAGE(C33:C35)+AVERAGE(F33:F35)) -> 0.13729357 | E16: =1-D16 -> 0.86270643 | F16: 0.27 | G16: =(C16*E16)/(E16+D16*(1-F16)) -> 0.72652485 | H16: =G16*(1+$D$25/$E$25*(1-F16)) -> 0.82091294
B17: =[1]Beta!D7 -> Keurig Dr. Pepper | C17: =Beta!E7 -> 0.51960989 | D17: =AVERAGE($C$43:$C$45)/(AVERAGE($C$43:$C$45)+AVERAGE($F$43:$F$45)) -> 0.19730473 | E17: =1-D17 -> 0.80269527 | F17: 0.27 | G17: =(C17*E17)/(E17+D17*(1-F17)) -> 0.44055793 | H17: =G17*(1+$D$25/$E$25*(1-F17)) -> 0.49779399
B18: =[1]Beta!D8 -> Monster Beverages | C18: =Beta!E8 -> 0.84032716 | D18: =AVERAGE(C48:C50)/(AVERAGE(C48:C50)+AVERAGE(F48:F50)) -> 0 | E18: =1-D18 -> 1 | F18: 0.27 | G18: =(C18*E18)/(E18+D18*(1-F18)) -> 0.84032716 | H18: =G18*(1+$D$25/$E$25*(1-F18)) -> 0.94950014
B19: =[1]Beta!D12 -> Mondelez | C19: =Beta!E12 -> 0.6570591 | D19: =AVERAGE($C$53:$C$55)/(AVERAGE($C$53:$C$55)+AVERAGE($F$53:$F$55)) -> 0.17729387 | E19: =1-D19 -> 0.82270613 | F19: 0.27 | G19: =(C19*E19)/(E19+D19*(1-F19)) -> 0.56774409 | H19: =G19*(1+$D$25/$E$25*(1-F19)) -> 0.64150382
B20: =[1]Beta!D13 -> Hershey Co. | C20: =Beta!E13 -> 0.58104066 | D20: =AVERAGE($C$58:$C$60)/(AVERAGE($C$58:$C$60)+AVERAGE($F$58:$F$60)) -> 0.13189005 | E20: =1-D20 -> 0.86810995 | F20: 0.27 | G20: =(C20*E20)/(E20+D20*(1-F20)) -> 0.52303253 | H20: =G20*(1+$D$25/$E$25*(1-F20)) -> 0.59098347
B21: =[1]Beta!D15 -> Constellation Brands | C21: =Beta!E15 -> 1.1962912 | D21: =AVERAGE($C$63:$C$65)/(AVERAGE($C$63:$C$65)+AVERAGE($F$63:$F$65)) -> 0.21075915 | E21: =1-D21 -> 0.78924085 | F21: 0.27 | G21: =(C21*E21)/(E21+D21*(1-F21)) -> 1.0011312 | H21: =G21*(1+$D$25/$E$25*(1-F21)) -> 1.1311954
D22: =MEDIAN(D16:D21) -> 0.15729372 | E22: =MEDIAN(E16:E21) -> 0.84270628 | H22: =MEDIAN(H16:H21) -> 0.73120838 | I22: this is bottoms up beta
B23: Beta Calculation for Target Co
A24: 1 | B24: Bottoms Up beta
A25: 2 | B25: Regression beta | C25: =Beta!E5 -> 0.67732435 | D25: =AVERAGE(C38:C40)/(AVERAGE(C38:C40)+AVERAGE(F38:F40)) -> 0.15108108 | E25: =1-D25 -> 0.84891892 | F25: =F21 -> 0.27 | G25: =(C25*E25)/(E25+D25*(1-F25)) -> 0.59944599 | H25: =G25*(1+$D$25/$E$25*(1-F25)) -> 0.67732435
B30: Calculation of Capital Structure of Peer Group Companies
C31: Debt | D31: Equity
B32: Coca Cola | D32: Share Price | E32: Shares O/S | F32: M.Cap | G32: Tax Rate
B33: 45134 | C33: =4828+35626+1171 -> 41625 | D33: 62.44 | E33: =4324344812/10^6 -> 4324.3448 | F33: =E33*D33 -> 270012.09 | G33: 0.27
B34: 44769 | C34: =4358+788+36755 -> 41901 | D34: 63.01 | E34: =4324629174/10^6 -> 4324.6292 | F34: =E34*D34 -> 272494.88 | G34: 0.27
B35: 44403 | C35: =1867+337+39804 -> 42008 | D35: 57.06 | E35: =4316618703/10^6 -> 4316.6187 | F35: =E35*D35 -> 246306.26 | G35: 0.27
B37: Pepsico
B38: 45120 | C38: =7613+36008 -> 43621 | D38: 187.53 | E38: =1376580611/10^6 -> 1376.5806 | F38: =E38*D38 -> 258150.16 | G38: 0.27
B39: 44754 | C39: =6032+33247 -> 39279 | D39: 169.5 | E39: =1380084844/10^6 -> 1380.0848 | F39: =E39*D39 -> 233924.38 | G39: 0.27
B40: 44390 | C40: =4264+38034 -> 42298 | D40: 152.96 | E40: =1382114956/10^6 -> 1382.115 | F40: =E40*D40 -> 211408.3 | G40: 0.27
B42: Keurig Dr. Pepper
B43: 45134 | C43: =2635+9934 -> 12569 | D43: 33.76 | E43: =1397259384/10^6 -> 1397.2594 | F43: =E43*D43 -> 47171.477 | G43: 0.27
B44: 44770 | C44: =0+11555 -> 11555 | D44: 38.5 | E44: =1416070252/10^6 -> 1416.0703 | F44: =E44*D44 -> 54518.705 | G44: 0.27
B45: 44406 | C45: =1328+11721 -> 13049 | D45: 34.95 | E45: =1417476953/10^6 -> 1417.477 | F45: =E45*D45 -> 49540.82 | G45: 0.27
B47: Monster Beverages
B48: 45051 | C48: 0 | D48: 59.71 | E48: =1046711932/10^6 -> 1046.7119 | F48: =E48*D48 -> 62499.169 | G48: 0.27
...

Sheet Beta
C1: BETA CALCULATION
K3: we don’t calculate beta on absolute numbers as the change will nor be apppropriate
D4: Competitors | E4: Beta | F4: Market Cap | G4: R sq
D5: Pepsico | E5: =SLOPE($E$21:$E$258,$BA$21:$BA$258) -> 0.67732435 | F5: 249 | G5: =RSQ($E$21:$E$258,$BA$21:$BA$258) -> 0.4523775
D6: Coca Cola | E6: =SLOPE($I$21:$I$258,$BA$21:$BA$258) -> 0.81092836 | F6: 261 | G6: =RSQ($I$21:$I$258,$BA$21:$BA$258) -> 0.49260567 | K6: regression eq- | L6: Y= a+bX
D7: Keurig Dr. Pepper | E7: =SLOPE($M$21:$M$258,$BA$21:$BA$258) -> 0.51960989 | F7: 47 | G7: =RSQ($M$21:$M$258,$BA$21:$BA$258) -> 0.26749515 | L7: Y is dependent, X is independent
D8: Monster Beverages | E8: =SLOPE($Q$21:$Q$258,$BA$21:$BA$258) -> 0.84032716 | F8: 60.9 | G8: =RSQ($Q$21:$Q$258,$BA$21:$BA$258) -> 0.4165087 | L8: a, b are constants
D9: Hormel Foods | E9: =SLOPE($U$21:$U$258,$BA$21:$BA$258) -> 0.19151187 | F9: 21.665 | G9: =RSQ($U$21:$U$258,$BA$21:$BA$258) -> 0.036866699 | L9: stock- dependent
D10: Kellogg Company | E10: =SLOPE($Y$21:$Y$258,$BA$21:$BA$258) -> 0.38387877 | F10: 21.126 | G10: =RSQ($Y$21:$Y$258,$BA$21:$BA$258) -> 0.13573576 | L10: market- independent
D11: Kraft Heinz Co. | E11: =SLOPE($AC$21:$AC$258,$BA$21:$BA$258) -> 0.57392097 | F11: 41.357 | G11: =RSQ($AC$21:$AC$258,$BA$21:$BA$258) -> 0.15064376
D12: Mondelez | E12: =SLOPE($AG$21:$AG$258,$BA$21:$BA$258) -> 0.6570591 | F12: 97.365 | G12: =RSQ($AG$21:$AG$258,$BA$21:$BA$258) -> 0.41399993 | J12: pepsico- regression beta
D13: Hershey Co. | E13: =SLOPE($AK$21:$AK$258,$BA$21:$BA$258) -> 0.58104066 | F13: 44.433 | G13: =RSQ($AK$21:$AK$258,$BA$21:$BA$258) -> 0.27795919 | J13: rest companies- bottoms up beta | O13: rsq- systematic risk
D14: Campbell Soup | E14: =SLOPE($AO$21:$AO$258,$BA$21:$BA$258) -> 0.23143192 | F14: 12.508 | G14: =RSQ($AO$21:$AO$258,$BA$21:$BA$258) -> 0.036177526 | J14: beta relevant- rsq=25 above
D15: Constellation Brands | E15: =SLOPE($AS$21:$AS$258,$BA$21:$BA$258) -> 1.1962912 | F15: 47.816 | G15: =RSQ($AS$21:$AS$258,$BA$21:$BA$258) -> 0.52522879
D16: General Mills | E16: =SLOPE($AW$21:$AW$258,$BA$21:$BA$258) -> 0.20453619 | F16: 39.683 | G16: =RSQ($AW$21:$AW$258,$BA$21:$BA$258) -> 0.040573428
D17: Source : marketscreener.com
D18: marketscreener.com
C19: Pepsico | G19: Coca-Cola | K19: Keurig Dr. Pepper | O19: Monster Beverage Corporation | S19: Hormel Foods Corporation (HFL) | W19: Kellogg Company | AA19: Kraft Heinz Co (KHC) | AE19: Mondelez (MDLZ) | AI19: Hershey Co. | AM19: Campbell Soup (CPB) | AQ19: Constellation Brands (STZ) | AU19: General Mills Inc (GIS) | AY19: S&P 500
C20: Date | D20: Adj Close | E20: % Change | G20: Date | H20: Adj Close | I20: % Change | K20: Date | L20: Adj Close | M20: % Change | O20: Date | P20: Adj Close | Q20: % Change | S20: Date | T20: Adj Close | U20: % Change | W20: Date | X20: Adj Close | Y20: % Change | AA20: Date | AB20: Adj Close | AC20: % Change | AE20: Date | AF20: Adj Close | AG20: % Change | AI20: Date | AJ20: Adj Close | AK20: % Change | AM20: Date | AN20: Adj Close | AO20: % Change | AQ20: Date | AR20: Adj Close | AS20: % Change | AU20: Date | AV20: Adj Close | AW20: % Change | AY20: Date | AZ20: Adj Close | BA20: % Change
C21: 07/30/2023 | D21: 184.6 | E21: =D21/D22-1 -> -0.030003678 | G21: 07/30/2023 | H21: 60.71 | I21: =H21/H22-1 -> -0.028329065 | K21: 07/30/2023 | L21: 33.6 | M21: =L21/L22-1 -> -0.0094339623 | O21: 07/30/2023 | P21: 55.11 | Q21: =P21/P22-1 -> -0.05227859 | S21: 07/30/2023 | T21: 40.54 | U21: =T21/T22-1 -> -0.012183236 | W21: 07/30/2023 | X21: 64.8 | Y21: =X21/X22-1 -> -0.041136431 | AA21: 07/30/2023 | AB21: 35.28 | AC21: =AB21/AB22-1 -> -0.024336283 | AE21: 07/30/2023 | AF21: 73.92 | AG21: =AF21/AF22-1 -> -0.014925373 | AI21: 07/30/2023 | AJ21: 228.23 | AK21: =AJ21/AJ22-1 -> -0.031446274 | AM21: 07/30/2023 | AN21: 45.15 | AO21: =AN21/AN22-1 -> -0.023783784 | AQ21: 07/30/2023 | AR21: 268.02 | AS21: =AR21/AR22-1 -> -0.016440367 | AU21: 07/30/2023 | AV21: 73.59 | AW21: =AV21/AV22-1 -> -0.024652087 | AY21: 07/30/2023 | AZ21: 4478.03 | BA21: =AZ21/AZ22-1 -> -0.02274002
C22: 07/23/2023 | D22: 190.31 | E22: =D22/D23-1 -> 0.00078880942 | G22: 07/23/2023 | H22: 62.48 | I22: =H22/H23-1 -> 0.00064061499 | K22: 07/23/2023 | L22: 33.92 | M22: =L22/L23-1 -> 0.041129527 | O22: 07/23/2023 | P22: 58.15 | Q22: =P22/P23-1 -> 0.0008605852 | S22: 07/23/2023 | T22: 41.04 | U22: =T22/T23-1 -> 0.022421525 | W22: 07/23/2023 | X22: 67.58 | Y22: =X22/X23-1 -> -0.0029507229 | AA22: 07/23/2023 | AB22: 36.16 | AC22: =AB22/AB23-1 -> -0.0044052863 | AE22: 07/23/2023 | AF22: 75.04 | AG22: =AF22/AF23-1 -> 0.014328197 | AI22: 07/23/2023 | AJ22: 235.64 | AK22: =AJ22/AJ23-1 -> -0.044599416 | AM22: 07/23/2023 | AN22: 46.25 | AO22: =AN22/AN23-1 -> -0.0017267429 | AQ22: 07/23/2023 | AR22: 272.5 | AS22: =AR22/AR23-1 -> 0.011131725 | AU22: 07/23/2023 | AV22: 75.45 | AW22: =AV22/AV23-1 -> -0.02012987 | AY22: 07/23/2023 | AZ22: 4582.23 | BA22: =AZ22/AZ23-1 -> 0.010116085
C23: 07/16/2023 | D23: 190.16 | E23: =D23/D24-1 -> 0.010360767 | G23: 07/16/2023 | H23: 62.44 | I23: =H23/H24-1 -> 0.025287356 | K23: 07/16/2023 | L23: 32.58 | M23: =L23/L24-1 -> 0.029058749 | O23: 07/16/2023 | P23: 58.1 | Q23: =P23/P24-1 -> 0.01378468 | S23: 07/16/2023 | T23: 40.14 | U23: =T23/T24-1 -> 0.00024919013 | W23: 07/16/2023 | X23: 67.78 | Y23: =X23/X24-1 -> 0.0032563647 | AA23: 07/16/2023 | AB23: 36.32 | AC23: =AB23/AB24-1 -> 0.013110181 | AE23: 07/16/2023 | AF23: 73.98 | AG23: =AF23/AF24-1 -> 0.023519646 | AI23: 07/16/2023 | AJ23: 246.64 | AK23: =AJ23/AJ24-1 -> 0.032528153 | AM23: 07/16/2023 | AN23: 46.33 | AO23: =AN23/AN24-1 -> 0.020709407 | AQ23: 07/16/2023 | AR23: 269.5 | AS23: =AR23/AR24-1 -> 0.054918386 | AU23: 07/16/2023 | AV23: 77 | AW23: =AV23/AV24-1 -> 0.026529796 | AY23: 07/16/2023 | AZ23: 4536.34 | BA23: =AZ23/AZ24-1 -> 0.0068628452
C24: 45176 | D24: 188.21 | E24: =D24/D25-1 -> 0.028020537 | G24: 45176 | H24: 60.9 | I24: =H24/H25-1 -> 0.019076305 | K24: 45176 | L24: 31.66 | M24: =L24/L25-1 -> -0.0031486146 | O24: 45176 | P24: 57.31 | Q24: =P24/P25-1 -> 0.025774118 | S24: 45176 | T24: 40.13 | U24: =T24/T25-1 -> 0.019822109 | W24: 45176 | X24: 67.56 | Y24: =X24/X25-1 -> 0.0055067718 | AA24: 45176 | AB24: 35.85 | AC24: =AB24/AB25-1 -> 0.010998308 | AE24: 45176 | AF24: 72.28 | AG24: =AF24/AF25-1 -> 0.0038888889 | AI24: 45176 | AJ24: 238.87 | AK24: =AJ24/AJ25-1 -> -0.016914972 | AM24: 45176 | AN24: 45.39 | AO24: =AN24/AN25-1 -> -0.0032938076 | AQ24: 45176 | AR24: 255.47 | AS24: =AR24/AR25-1 -> 0.007810959 | AU24: 45176 | AV24: 75.01 | AW24: =AV24/AV25-1 -> -0.0021285087 | AY24: 45176 | AZ24: 4505.42 | BA24: =AZ24/AZ25-1 -> 0.024203503
C25: 44964 | D25: 183.08 | E25: =D25/D26-1 -> -0.011553828 | G25: 44964 | H25: 59.76 | I25: =H25/H26-1 -> -0.0076386583 | K25: 44964 | L25: 31.76 | M25: =L25/L26-1 -> 0.015669971 | O25: 44964 | P25: 55.87 | Q25: =P25/P26-1 -> -0.027332869 | S25: 44964 | T25: 39.35 | U25: =T25/T26-1 -> -0.021631029 | W25: 44964 | X25: 67.19 | Y25: =X25/X26-1 -> -0.003115727 | AA25: 44964 | AB25: 35.46 | AC25: =AB25/AB26-1 -> -0.0011267606 | AE25: 44964 | AF25: 72 | AG25: =AF25/AF26-1 -> -0.012887305 | AI25: 44964 | AJ25: 242.98 | AK25: =AJ25/AJ26-1 -> -0.026912295 | AM25: 44964 | AN25: 45.54 | AO25: =AN25/AN26-1 -> -0.0037190987 | AQ25: 44964 | AR25: 253.49 | AS25: =AR25/AR26-1 -> 0.029902897 | AU25: 44964 | AV25: 75.17 | AW25: =AV25/AV26-1 -> -0.019947849 | AY25: 44964 | AZ25: 4398.95 | BA25: =AZ25/AZ26-1 -> -0.011556317
C26: 06/25/2023 | D26: 185.22 | E26: =D26/D27-1 -> -0.0045681733 | G26: 06/25/2023 | H26: 60.22 | I26: =H26/H27-1 -> -0.016013072 | K26: 06/25/2023 | L26: 31.27 | M26: =L26/L27-1 -> 0.0028864657 | O26: 06/25/2023 | P26: 57.44 | Q26: =P26/P27-1 -> -0.028252411 | S26: 06/25/2023 | T26: 40.22 | U26: =T26/T27-1 -> -0.0061774154 | W26: 06/25/2023 | X26: 67.4 | Y26: =X26/X27-1 -> 0.034376918 | AA26: 06/25/2023 | AB26: 35.5 | AC26: =AB26/AB27-1 -> -0.011417432 | AE26: 06/25/2023 | AF26: 72.94 | AG26: =AF26/AF27-1 -> -0.0021887825 | AI26: 06/25/2023 | AJ26: 249.7 | AK26: =AJ26/AJ27-1 -> -0.036242232 | AM26: 06/25/2023 | AN26: 45.71 | AO26: =AN26/AN27-1 -> 0.0026321562 | AQ26: 06/25/2023 | AR26: 246.13 | AS26: =AR26/AR27-1 -> 0.015471574 | AU26: 06/25/2023 | AV26: 76.7 | AW26: =AV26/AV27-1 -> -0.056812592 | AY26: 06/25/2023 | AZ26: 4450.38 | BA26: =AZ26/AZ27-1 -> 0.02346878
C27: 06/18/2023 | D27: 186.07 | E27: =D27/D28-1 -> 0.00016125564 | G27: 06/18/2023 | H27: 61.2 | I27: =H27/H28-1 -> -0.0076212097 | K27: 06/18/2023 | L27: 31.18 | M27: =L27/L28-1 -> -0.030774013 | O27: 06/18/2023 | P27: 59.11 | Q27: =P27/P28-1 -> 0.011291702 | S27: 06/18/2023 | T27: 40.47 | U27: =T27/T28-1 -> -0.019384541 | W27: 06/18/2023 | X27: 65.16 | Y27: =X27/X28-1 -> -0.017046312 | AA27: 06/18/2023 | AB27: 35.91 | AC27: =AB27/AB28-1 -> -0.02919708 | AE27: 06/18/2023 | AF27: 73.1 | AG27: =AF27/AF28-1 -> -0.0063884736 | AI27: 06/18/2023 | AJ27: 259.09 | AK27: =AJ27/AJ28-1 -> -0.0062519178 | AM27: 06/18/2023 | AN27: 45.59 | AO27: =AN27/AN28-1 -> -0.017880224 | AQ27: 06/18/2023 | AR27: 242.38 | AS27: =AR27/AR28-1 -> -0.014835589 | AU27: 06/18/2023 | AV27: 81.32 | AW27: =AV27/AV28-1 -> 0.0075579234 | AY27: 06/18/2023 | AZ27: 4348.33 | BA27: =AZ27/AZ28-1 -> -0.013892448
C28: 45236 | D28: 186.04 | E28: =D28/D29-1 -> 0.02023581 | G28: 45236 | H28: 61.67 | I28: =H28/H29-1 -> 0.019844551 | K28: 45236 | L28: 32.17 | M28: =L28/L29-1 -> 0.027467263 | O28: 45236 | P28: 58.45 | Q28: =P28/P29-1 -> 0.020960699 | S28: 45236 | T28: 41.27 | U28: =T28/T29-1 -> 0.0097871299 | W28: 45236 | X28: 66.29 | Y28: =X28/X29-1 -> -0.012954139 | AA28: 45236 | AB28: 36.99 | AC28: =AB28/AB29-1 -> 0.0029826464 | AE28: 45236 | AF28: 73.57 | AG28: =AF28/AF29-1 -> 0.0082225572 | AI28: 45236 | AJ28: 260.72 | AK28: =AJ28/AJ29-1 -> 0.019154093 | AM28: 45236 | AN28: 46.42 | AO28: =AN28/AN29-1 -> 0.0080347448 | AQ28: 45236 | AR28: 246.03 | AS28: =AR28/AR29-1 -> 0.018293945 | AU28: 45236 | AV28: 80.71 | AW28: =AV28/AV29-1 -> -0.019319563 | AY28: 45236 | AZ28: 4409.59 | BA28: =AZ28/AZ29-1 -> 0.025757992
C29: 45022 | D29: 182.35 | E29: =D29/D30-1 -> -0.0092904488 | G29: 45022 | H29: 60.47 | I29: =H29/H30-1 -> -0.011281884 | K29: 45022 | L29: 31.31 | M29: =L29/L30-1 -> -0.0044515103 | O29: 45022 | P29: 57.25 | Q29: =P29/P30-1 -> -0.037491594 | S29: 45022 | T29: 40.87 | U29: =T29/T30-1 -> 0.0024527839 | W29: 45022 | X29: 67.16 | Y29: =X29/X30-1 -> -0.0034129693 | AA29: 45022 | AB29: 36.88 | AC29: =AB29/AB30-1 -> -0.042326668 | AE29: 45022 | AF29: 72.97 | AG29: =AF29/AF30-1 -> -0.017503703 | AI29: 45022 | AJ29: 255.82 | AK29: =AJ29/AJ30-1 -> -0.019508643 | AM29: 45022 | AN29: 46.05 | AO29: =AN29/AN30-1 -> -0.10530406 | AQ29: 45022 | AR29: 241.61 | AS29: =AR29/AR30-1 -> -0.015524407 | AU29: 45022 | AV29: 82.3 | AW29: =AV29/AV30-1 -> -0.027071758 | AY29: 45022 | AZ29: 4298.86 | BA29: =AZ29/AZ30-1 -> 0.0038506715
C30: 05/28/2023 | D30: 184.06 | E30: =D30/D31-1 -> 0.0026146639 | G30: 05/28/2023 | H30: 61.16 | I30: =H30/H31-1 -> 0.01493528 | K30: 05/28/2023 | L30: 31.45 | M30: =L30/L31-1 -> 0.0012734798 | O30: 05/28/2023 | P30: 59.48 | Q30: =P30/P31-1 -> 0.032459642 | S30: 05/28/2023 | T30: 40.77 | U30: =T30/T31-1 -> 0.059786847 | W30: 05/28/2023 | X30: 67.39 | Y30: =X30/X31-1 -> -0.0041377272 | AA30: 05/28/2023 | AB30: 38.51 | AC30: =AB30/AB31-1 -> 0.0044340115 | AE30: 05/28/2023 | AF30: 74.27 | AG30: =AF30/AF31-1 -> -0.011446826 | AI30: 05/28/2023 | AJ30: 260.91 | AK30: =AJ30/AJ31-1 -> 0.012377774 | AM30: 05/28/2023 | AN30: 51.47 | AO30: =AN30/AN31-1 -> -0.00077654824 | AQ30: 05/28/2023 | AR30: 245.42 | AS30: =AR30/AR31-1 -> 0.053847475 | AU30: 05/28/2023 | AV30: 84.59 | AW30: =AV30/AV31-1 -> 0.0048705156 | AY30: 05/28/2023 | AZ30: 4282.37 | BA30: =AZ30/AZ31-1 -> 0.018290552
C31: 05/21/2023 | D31: 183.58 | E31: =D31/D32-1 -> -0.043056714 | G31: 05/21/2023 | H31: 60.26 | I31: =H31/H32-1 -> -0.040904027 | K31: 05/21/2023 | L31: 31.41 | M31: =L31/L32-1 -> -0.013195099 | O31: 05/21/2023 | P31: 57.61 | Q31: =P31/P32-1 -> -0.034684987 | S31: 05/21/2023 | T31: 38.47 | U31: =T31/T32-1 -> -0.022114896 | W31: 05/21/2023 | X31: 67.67 | Y31: =X31/X32-1 -> -0.023943459 | AA31: 05/21/2023 | AB31: 38.34 | AC31: =AB31/AB32-1 -> -0.018684413 | AE31: 05/21/2023 | AF31: 75.13 | AG31: =AF31/AF32-1 -> -0.025045419 | AI31: 05/21/2023 | AJ31: 257.72 | AK31: =AJ31/AJ32-1 -> -0.031273493 | AM31: 05/21/2023 | AN31: 51.51 | AO31: =AN31/AN32-1 -> -0.022209567 | AQ31: 05/21/2023 | AR31: 232.88 | AS31: =AR31/AR32-1 -> -0.010242679 | AU31: 05/21/2023 | AV31: 84.18 | AW31: =AV31/AV32-1 -> -0.039370079 | AY31: 05/21/2023 | AZ31: 4205.45 | BA31: =AZ31/AZ32-1 -> 0.0032132787
C32: 05/14/2023 | D32: 191.84 | E32: =D32/D33-1 -> -0.021823373 | G32: 05/14/2023 | H32: 62.83 | I32: =H32/H33-1 -> -0.019965684 | K32: 05/14/2023 | L32: 31.83 | M32: =L32/L33-1 -> -0.025711662 | O32: 05/14/2023 | P32: 59.68 | Q32: =P32/P33-1 -> 0.0023513604 | S32: 05/14/2023 | T32: 39.34 | U32: =T32/T33-1 -> -0.022365805 | W32: 05/14/2023 | X32: 69.33 | Y32: =X32/X33-1 -> -0.020901003 | AA32: 05/14/2023 | AB32: 39.07 | AC32: =AB32/AB33-1 -> -0.039104771 | AE32: 05/14/2023 | AF32: 77.06 | AG32: =AF32/AF33-1 -> -0.010529019 | AI32: 05/14/2023 | AJ32: 266.04 | AK32: =AJ32/AJ33-1 -> -0.031102047 | AM32: 05/14/2023 | AN32: 52.68 | AO32: =AN32/AN33-1 -> -0.030369961 | AQ32: 05/14/2023 | AR32: 235.29 | AS32: =AR32/AR33-1 -> 0.033106476 | AU32: 05/14/2023 | AV32: 87.63 | AW32: =AV32/AV33-1 -> -0.032888202 | AY32: 05/14/2023 | AZ32: 4191.98 | BA32: =AZ32/AZ33-1 -> 0.016464278
C33: 45112 | D33: 196.12 | E33: =D33/D34-1 -> 0.0095228291 | G33: 45112 | H33: 64.11 | I33: =H33/H34-1 -> 0.0014058107 | K33: 45112 | L33: 32.67 | M33: =L33/L34-1 -> -0.016852242 | O33: 45112 | P33: 59.54 | Q33: =P33/P34-1 -> -0.0028470943 | S33: 45112 | T33: 40.24 | U33: =T33/T34-1 -> -0.023300971 | W33: 45112 | X33: 70.81 | Y33: =X33/X34-1 -> 0.0065387349 | AA33: 45112 | AB33: 40.66 | AC33: =AB33/AB34-1 -> -0.015972894 | AE33: 45112 | AF33: 77.88 | AG33: =AF33/AF34-1 -> 0.0041258381 | AI33: 45112 | AJ33: 274.58 | AK33: =AJ33/AJ34-1 -> -0.0027240039 | AM33: 45112 | AN33: 54.33 | AO33: =AN33/AN34-1 -> -0.0074899525 | AQ33: 45112 | AR33: 227.75 | AS33: =AR33/AR34-1 -> 0.019289295 | AU33: 45112 | AV33: 90.61 | AW33: =AV33/AV34-1 -> 0.008907694 | AY33: 45112 | AZ33: 4124.08 | BA33: =AZ33/AZ34-1 -> -0.0029422786
C34: 04/30/2023 | D34: 194.27 | E34: =D34/D35-1 -> 0.017706533 | G34: 04/30/2023 | H34: 64.02 | I34: =H34/H35-1 -> -0.0020265004 | K34: 04/30/2023 | L34: 33.23 | M34: =L34/L35-1 -> 0.016207951 | O34: 04/30/2023 | P34: 59.71 | Q34: =P34/P35-1 -> 0.06625 | S34: 04/30/2023 | T34: 41.2 | U34: =T34/T35-1 -> 0.018793274 | W34: 04/30/2023 | X34: 70.35 | Y34: =X34/X35-1 -> 0.0083130285 | AA34: 04/30/2023 | AB34: 41.32 | AC34: =AB34/AB35-1 -> 0.052202699 | AE34: 04/30/2023 | AF34: 77.56 | AG34: =AF34/AF35-1 -> 0.010948905 | AI34: 04/30/2023 | AJ34: 275.33 | AK34: =AJ34/AJ35-1 -> 0.0083131912 | AM34: 04/30/2023 | AN34: 54.74 | AO34: =AN34/AN35-1 -> 0.0081031308 | AQ34: 04/30/2023 | AR34: 223.44 | AS34: =AR34/AR35-1 -> -0.026277945 | AU34: 04/30/2023 | AV34: 89.81 | AW34: =AV34/AV35-1 -> 0.013313776 | AY34: 04/30/2023 | AZ34: 4136.25 | BA34: =AZ34/AZ35-1 -> -0.0079698188
C35: 04/23/2023 | D35: 190.89 | E35: =D35/D36-1 -> 0.029556119 | G35: 04/23/2023 | H35: 64.15 | I35: =H35/H36-1 -> 0.0015612802 | K35: 04/23/2023 | L35: 32.7 | M35: =L35/L36-1 -> -0.073916737 | O35: 04/23/2023 | P35: 56 | Q35: =P35/P36-1 -> 0.0552101 | S35: 04/23/2023 | T35: 40.44 | U35: =T35/T36-1 -> 0.014805521 | W35: 04/23/2023 | X35: 69.77 | Y35: =X35/X36-1 -> 0.0359317 | AA35: 04/23/2023 | AB35: 39.27 | AC35: =AB35/AB36-1 -> 0.0012748598 | AE35: 04/23/2023 | AF35: 76.72 | AG35: =AF35/AF36-1 -> 0.075715087 | AI35: 04/23/2023 | AJ35: 273.06 | AK35: =AJ35/AJ36-1 -> 0.046808511 | AM35: 04/23/2023 | AN35: 54.3 | AO35: =AN35/AN36-1 -> 0.011738401 | AQ35: 04/23/2023 | AR35: 229.47 | AS35: =AR35/AR36-1 -> 0.013381028 | AU35: 04/23/2023 | AV35: 88.63 | AW35: =AV35/AV36-1 -> 0.013493425 | AY35: 04/23/2023 | AZ35: 4169.48 | BA35: =AZ35/AZ36-1 -> 0.0086996071
C36: 04/16/2023 | D36: 185.41 | E36: =D36/D37-1 -> 0.010353659 | G36: 04/16/2023 | H36: 64.05 | I36: =H36/H37-1 -> 0.015860428 | K36: 04/16/2023 | L36: 35.31 | M36: =L36/L37-1 -> 0.005982906 | O36: 04/16/2023 | P36: 53.07 | Q36: =P36/P37-1 -> 0.0097031963 | S36: 04/16/2023 | T36: 39.85 | U36: =T36/T37-1 -> 0.015028018 | W36: 04/16/2023 | X36: 67.35 | Y36: =X36/X37-1 -> 0.0052238806 | AA36: 04/16/2023 | AB36: 39.22 | AC36: =AB36/AB37-1 -> 0.0030690537 | AE36: 04/16/2023 | AF36: 71.32 | AG36: =AF36/AF37-1 -> 0.021630139 | AI36: 04/16/2023 | AJ36: 260.85 | AK36: =AJ36/AJ37-1 -> 0.017832059 | AM36: 04/16/2023 | AN36: 53.67 | AO36: =AN36/AN37-1 -> -0.02026287 | AQ36: 04/16/2023 | AR36: 226.44 | AS36: =AR36/AR37-1 -> -0.0078429654 | AU36: 04/16/2023 | AV36: 87.45 | AW36: =AV36/AV37-1 -> 0.010281885 | AY36: 04/16/2023 | AZ36: 4133.52 | BA36: =AZ36/AZ37-1 -> -0.0009957367
C37: 45173 | D37: 183.51 | E37: =D37/D38-1 -> -0.0046105446 | G37: 45173 | H37: 63.05 | I37: =H37/H38-1 -> 0.0033418205 | K37: 45173 | L37: 35.1 | M37: =L37/L38-1 -> -0.015151515 | O37: 45173 | P37: 52.56 | Q37: =P37/P38-1 -> 0 | S37: 45173 | T37: 39.26 | U37: =T37/T38-1 -> -0.026048127 | W37: 45173 | X37: 67 | Y37: =X37/X38-1 -> -0.014560965 | AA37: 45173 | AB37: 39.1 | AC37: =AB37/AB38-1 -> -0.0010219724 | AE37: 45173 | AF37: 69.81 | AG37: =AF37/AF38-1 -> -0.017452498 | AI37: 45173 | AJ37: 256.28 | AK37: =AJ37/AJ38-1 -> -0.0138146 | AM37: 45173 | AN37: 54.78 | AO37: =AN37/AN38-1 -> -0.012439156 | AQ37: 45173 | AR37: 228.23 | AS37: =AR37/AR38-1 -> 0.015981125 | AU37: 45173 | AV37: 86.56 | AW37: =AV37/AV38-1 -> -0.0039125432 | AY37: 45173 | AZ37: 4137.64 | BA37: =AZ37/AZ38-1 -> 0.0079463681
C38: 44961 | D38: 184.36 | E38: =D38/D39-1 -> 0.011300055 | G38: 44961 | H38: 62.84 | I38: =H38/H39-1 -> 0.013058198 | K38: 44961 | L38: 35.64 | M38: =L38/L39-1 -> 0.010204082 | O38: 44961 | P38: 52.56 | Q38: =P38/P39-1 -> -0.02684688 | S38: 44961 | T38: 40.31 | U38: =T38/T39-1 -> 0.010782347 | W38: 44961 | X38: 67.99 | Y38: =X38/X39-1 -> 0.015382318 | AA38: 44961 | AB38: 39.14 | AC38: =AB38/AB39-1 -> 0.012154125 | AE38: 44961 | AF38: 71.05 | AG38: =AF38/AF39-1 -> 0.019076305 | AI38: 44961 | AJ38: 259.87 | AK38: =AJ38/AJ39-1 -> 0.021461421 | AM38: 44961 | AN38: 55.47 | AO38: =AN38/AN39-1 -> 0.0089123318 | AQ38: 44961 | AR38: 224.64 | AS38: =AR38/AR39-1 -> -0.0055336668 | AU38: 44961 | AV38: 86.9 | AW38: =AV38/AV39-1 -> 0.016849988 | AY38: 44961 | AZ38: 4105.02 | BA38: =AZ38/AZ39-1 -> -0.0010439709
C39: 03/26/2023 | D39: 182.3 | E39: =D39/D40-1 -> 0.017923949 | G39: 03/26/2023 | H39: 62.03 | I39: =H39/H40-1 -> 0.018555008 | K39: 03/26/2023 | L39: 35.28 | M39: =L39/L40-1 -> 0.011757958 | O39: 03/26/2023 | P39: 54.01 | Q39: =P39/P40-1 -> 0.037855496 | S39: 03/26/2023 | T39: 39.88 | U39: =T39/T40-1 -> 0.031824062 | W39: 03/26/2023 | X39: 66.96 | Y39: =X39/X40-1 -> 0.022758515 | AA39: 03/26/2023 | AB39: 38.67 | AC39: =AB39/AB40-1 -> 0.012833944 | AE39: 03/26/2023 | AF39: 69.72 | AG39: =AF39/AF40-1 -> 0.0098493627 | AI39: 03/26/2023 | AJ39: 254.41 | AK39: =AJ39/AJ40-1 -> 0.026426208 | AM39: 03/26/2023 | AN39: 54.98 | AO39: =AN39/AN40-1 -> 0.0080674734 | AQ39: 03/26/2023 | AR39: 225.89 | AS39: =AR39/AR40-1 -> 0.036430374 | AU39: 03/26/2023 | AV39: 85.46 | AW39: =AV39/AV40-1 -> 0.0077830189 | AY39: 03/26/2023 | AZ39: 4109.31 | BA39: =AZ39/AZ40-1 -> 0.034832624
C40: 03/19/2023 | D40: 179.09 | E40: =D40/D41-1 -> 0.022611774 | G40: 03/19/2023 | H40: 60.9 | I40: =H40/H41-1 -> 0.014661779 | K40: 03/19/2023 | L40: 34.87 | M40: =L40/L41-1 -> 0.00028686173 | O40: 03/19/2023 | P40: 52.04 | Q40: =P40/P41-1 -> 0.010681686 | S40: 03/19/2023 | T40: 38.65 | U40: =T40/T41-1 -> 0.0078226858 | W40: 03/19/2023 | X40: 65.47 | Y40: =X40/X41-1 -> 0.011275873 | AA40: 03/19/2023 | AB40: 38.18 | AC40: =AB40/AB41-1 -> 0.014615998 | AE40: 03/19/2023 | AF40: 69.04 | AG40: =AF40/AF41-1 -> 0.039759036 | AI40: 03/19/2023 | AJ40: 247.86 | AK40: =AJ40/AJ41-1 -> 0.019370759 | AM40: 03/19/2023 | AN40: 54.54 | AO40: =AN40/AN41-1 -> 0.021730985 | AQ40: 03/19/2023 | AR40: 217.95 | AS40: =AR40/AR41-1 -> 0.033428165 | AU40: 03/19/2023 | AV40: 84.8 | AW40: =AV40/AV41-1 -> 0.062789823 | AY40: 03/19/2023 | AZ40: 3970.99 | BA40: =AZ40/AZ41-1 -> 0.01387669
C41: 45263 | D41: 175.13 | E41: =D41/D42-1 -> 0.018020113 | G41: 45263 | H41: 60.02 | I41: =H41/H42-1 -> 0.013680122 | K41: 45263 | L41: 34.86 | M41: =L41/L42-1 -> 0.015734266 | O41: 45263 | P41: 51.49 | Q41: =P41/P42-1 -> 0.027949691 | S41: 45263 | T41: 38.35 | U41: =T41/T42-1 -> -0.021184278 | W41: 45263 | X41: 64.74 | Y41: =X41/X42-1 -> 0.013304116 | AA41: 45263 | AB41: 37.63 | AC41: =AB41/AB42-1 -> -0.008170796 | AE41: 45263 | AF41: 66.4 | AG41: =AF41/AF42-1 -> 0.023112481 | AI41: 45263 | AJ41: 243.15 | AK41: =AJ41/AJ42-1 -> 0.022755952 | AM41: 45263 | AN41: 53.38 | AO41: =AN41/AN42-1 -> 0.016568273 | AQ41: 45263 | AR41: 210.9 | AS41: =AR41/AR42-1 -> -0.0051886792 | AU41: 45263 | AV41: 79.79 | AW41: =AV41/AV42-1 -> 0.016174223 | AY41: 45263 | AZ41: 3916.64 | BA41: =AZ41/AZ42-1 -> 0.014255786
...

Sheet Fixed Assets Schedule
A1: PepsiCo Inc.
A2: (in USD million except per Share Data)
A3: Property, Plant & Equipment | B3: 12 months | C3: 12 months | D3: 12 months | E3: 12 months | F3: 6 months | H3: 6 months | I3: 12 months | J3: 12 months | K3: 12 months | L3: 12 months
B4: Dec. 31, 2019 | C4: Dec. 31, 2020 | D4: Dec. 31, 2021 | E4: Dec. 31, 2022 | F4: Jun. 17, 2023 | H4: Dec. 31, 2023 | I4: Dec. 31, 2024 | J4: Dec. 31, 2025 | K4: Dec. 31, 2026 | L4: Dec. 31, 2027
A5: Opening Balance-WDV | B5: 17589 | C5: =B9 -> 19305 | D5: =C9 -> 21369 | E5: =D9 -> 22407 | F5: =E9 -> 24291 | H5: =F9 -> 24500 | I5: =H9 -> 29585.985 | J5: =I9 -> 30294.778 | K5: =J9 -> 32827.916 | L5: =K9 -> 35581.071
A6: Add: Net Addition during the Period | B6: =B7-B5 -> 4067 | C6: =C7-C5 -> 4522 | D6: =D7-D5 -> 3657 | E6: =E7-E5 -> 4569 | F6: =F7-F5 -> 1435.6514 | H6: =H7-H5 -> 6708.4559 | I6: =I7-I5 -> 4224.2602 | J6: =J7-J5 -> 6342.5553 | K6: =K7-K5 -> 6882.0533 | L6: =L7-L5 -> 7469.2155
A7: Total Depreciable Assets During the Year | B7: =B9+B8 -> 21656 | C7: =C9+C8 -> 23827 | D7: =D9+D8 -> 25026 | E7: =E9+E8 -> 26976 | F7: =F9+F8 -> 25726.651 | H7: ='PepsiCo-IS'!H6/'Fixed Assets Schedule'!H13 -> 31208.456 | I7: ='PepsiCo-IS'!I6/'Fixed Assets Schedule'!I13 -> 33810.245 | J7: ='PepsiCo-IS'!J6/'Fixed Assets Schedule'!J13 -> 36637.334 | K7: ='PepsiCo-IS'!K6/'Fixed Assets Schedule'!K13 -> 39709.97 | L7: ='PepsiCo-IS'!L6/'Fixed Assets Schedule'!L13 -> 43050.287
A8: Less: Depreciation during the year | B8: =B20 -> 2351 | C8: =C20 -> 2458 | D8: =D20 -> 2619 | E8: =E20 -> 2685 | F8: =F20 -> 1226.6514 | H8: =H7*H15/2 -> 1622.4711 | I8: =I7*I15 -> 3515.4667 | J8: =J7*J15 -> 3809.4171 | K8: =K7*K15 -> 4128.8987 | L8: =L7*L15 -> 4476.2127
A9: Closing Balance-WDV | B9: ='PepsiCo-BS'!B13 -> 19305 | C9: ='PepsiCo-BS'!C13 -> 21369 | D9: ='PepsiCo-BS'!D13 -> 22407 | E9: ='PepsiCo-BS'!E13 -> 24291 | F9: ='PepsiCo-BS'!F13 -> 24500 | H9: =H7-H8 -> 29585.985 | I9: =I7-I8 -> 30294.778 | J9: =J7-J8 -> 32827.916 | K9: =K7-K8 -> 35581.071 | L9: =L7-L8 -> 38574.074
A10: Source | H10: Calculation
A13: PPE Turnover Ratio | B13: ='PepsiCo-IS'!B6/'Fixed Assets Schedule'!B7 -> 3.1012652 | C13: ='PepsiCo-IS'!C6/'Fixed Assets Schedule'!C7 -> 2.9534562 | D13: ='PepsiCo-IS'!D6/'Fixed Assets Schedule'!D7 -> 3.1756573 | E13: ='PepsiCo-IS'!E6/'Fixed Assets Schedule'!E7 -> 3.2025504 | F13: ='PepsiCo-IS'!F6/'Fixed Assets Schedule'!F7 -> 1.5613381 | H13: =AVERAGE(B13:E13) -> 3.1082323 | I13: =H13 -> 3.1082323 | J13: =I13 -> 3.1082323 | K13: =J13 -> 3.1082323 | L13: =K13 -> 3.1082323
A15: Depreciation Rate | B15: =B8/B7 -> 0.10856114 | C15: =C8/C7 -> 0.10316028 | D15: =D8/D7 -> 0.10465116 | E15: =E8/E7 -> 0.099532918 | F15: =F8/F7 -> 0.047680181 | H15: =AVERAGE(B15:E15) -> 0.10397637 | I15: =H15 -> 0.10397637 | J15: =I15 -> 0.10397637 | K15: =J15 -> 0.10397637 | L15: =K15 -> 0.10397637
A18: Depreciation Exp | B18: ='PepsiCo-IS'!B11 -> 2196 | C18: ='PepsiCo-IS'!C11 -> 2331 | D18: ='PepsiCo-IS'!D11 -> 2496 | E18: ='PepsiCo-IS'!E11 -> 2564 | F18: ='PepsiCo-IS'!F11 -> 1162.3774 | G18: =AVERAGE(B21:F21) -> 0.947595 | H18: =$G$18*H20 -> 1537.4455 | I18: =$G$18*I20 -> 3331.2387 | J18: =$G$18*J20 -> 3609.7846 | K18: =$G$18*K20 -> 3912.5238 | L18: =$G$18*L20 -> 4241.6368
A19: Corporate Depreciation and Amort | B19: ='PepsiCo-IS'!B19 -> 155 | C19: ='PepsiCo-IS'!C19 -> 127 | D19: ='PepsiCo-IS'!D19 -> 123 | E19: ='PepsiCo-IS'!E19 -> 121 | F19: ='PepsiCo-IS'!F19 -> 64.273969 | H19: =H20-H18 -> 85.025593 | I19: =I20-I18 -> 184.22803 | J19: =J20-J18 -> 199.6325 | K19: =K20-K18 -> 216.37493 | L19: =L20-L18 -> 234.57592
B20: =B18+B19 -> 2351 | C20: =C18+C19 -> 2458 | D20: =D18+D19 -> 2619 | E20: =E18+E19 -> 2685 | F20: =F18+F19 -> 1226.6514 | H20: =H8 -> 1622.4711 | I20: =I8 -> 3515.4667 | J20: =J8 -> 3809.4171 | K20: =K8 -> 4128.8987 | L20: =L8 -> 4476.2127
B21: =B18/B20 -> 0.93407061 | C21: =C18/C20 -> 0.94833198 | D21: =D18/D20 -> 0.95303551 | E21: =E18/E20 -> 0.95493482 | F21: =F18/F20 -> 0.94760209
A22: Amortizable Intangible Assets, net | B22: 12 months | C22: 12 months | D22: 12 months | E22: 12 months | F22: 6 months | H22: 6 months | I22: 12 months | J22: 12 months | K22: 12 months | L22: 12 months
B23: Dec. 31, 2019 | C23: Dec. 31, 2020 | D23: Dec. 31, 2021 | E23: Dec. 31, 2022 | F23: Jun. 17, 2023 | H23: Dec. 31, 2023 | I23: Dec. 31, 2024 | J23: Dec. 31, 2025 | K23: Dec. 31, 2026 | L23: Dec. 31, 2027
A24: Opening Balance-WDV | C24: =B28 -> 1433 | D24: =C28 -> 1703 | E24: =D28 -> 1538 | F24: =E28 -> 1277 | H24: =F28 -> 1232 | I24: =H28 -> 1198.5631 | J24: =I28 -> 1133.5042 | K24: =J28 -> 1071.9767 | L24: =K28 -> 1013.7891
A25: Add: Net Addition during the Period | B25: =B26-B24 -> 1514 | C25: =C26-C24 -> 360 | D25: =D26-D24 -> -74 | E25: =E26-E24 -> -183 | F25: =F26-F24 -> -3.6513878 | H25: 0 | I25: 0 | J25: 0 | K25: 0 | L25: 0
A26: Total Amortizable Assets During the Year | B26: =B28+B27 -> 1514 | C26: =C28+C27 -> 1793 | D26: =D28+D27 -> 1629 | E26: =E28+E27 -> 1355 | F26: =F28+F27 -> 1273.3486 | H26: =H24+H25 -> 1232 | I26: =I24+I25 -> 1198.5631 | J26: =J24+J25 -> 1133.5042 | K26: =K24+K25 -> 1071.9767 | L26: =L24+L25 -> 1013.7891
A27: Less: Amortisation during the year | B27: ='PepsiCo-IS'!B20 -> 81 | C27: ='PepsiCo-IS'!C20 -> 90 | D27: ='PepsiCo-IS'!D20 -> 91 | E27: ='PepsiCo-IS'!E20 -> 78 | F27: ='PepsiCo-IS'!F20 -> 41.348612 | H27: =H26*H32/2 -> 33.436932 | I27: =I26*I32 -> 65.058882 | J27: =J26*J32 -> 61.527438 | K27: =K26*K32 -> 58.187684 | L27: =L26*L32 -> 55.029214
A28: Closing Balance-WDV | B28: ='PepsiCo-BS'!B14 -> 1433 | C28: ='PepsiCo-BS'!C14 -> 1703 | D28: ='PepsiCo-BS'!D14 -> 1538 | E28: ='PepsiCo-BS'!E14 -> 1277 | F28: ='PepsiCo-BS'!F14 -> 1232 | H28: =H26-H27 -> 1198.5631 | I28: =I26-I27 -> 1133.5042 | J28: =J26-J27 -> 1071.9767 | K28: =K26-K27 -> 1013.7891 | L28: =L26-L27 -> 958.75985
A29: Source | H29: Calculation
A32: Amortisation Rate | B32: =B27/B26 -> 0.053500661 | C32: =C27/C26 -> 0.050195204 | D32: =D27/D26 -> 0.055862492 | E32: =E27/E26 -> 0.057564576 | H32: =AVERAGE(B32:E32) -> 0.054280733 | I32: =H32 -> 0.054280733 | J32: =I32 -> 0.054280733 | K32: =J32 -> 0.054280733 | L32: =K32 -> 0.054280733

Sheet PepsiCo-BS
A1: PepsiCo Inc.
A2: (in USD million except per Share Data)
A3: Balance Sheet as of: | B3: Dec. 31, 2019 | C3: Dec. 31, 2020 | D3: Dec. 31, 2021 | E3: Dec. 31, 2022 | F3: June, 2023 | G3: Dec. 31, 2023 | H3: Dec. 31, 2024 | I3: Dec. 31, 2025 | J3: Dec. 31, 2026 | K3: Dec. 31, 2027
A4: ASSETS
A5: Cash And Equivalents | B5: 5509 | C5: 8185 | D5: 5596 | E5: 4954 | F5: 6116 | G5: ='Pepsico-CFS'!B35 -> 3131.3106 | H5: ='Pepsico-CFS'!C35 -> 4642.843 | I5: ='Pepsico-CFS'!D35 -> 4142.5892 | J5: ='Pepsico-CFS'!E35 -> 3762.4707 | K5: ='Pepsico-CFS'!F35 -> 4271.6655
A6: Short Term Investments | B6: 229 | C6: 1366 | D6: 392 | E6: 394 | F6: 338 | G6: =F6 -> 338 | H6: =G6 -> 338 | I6: =H6 -> 338 | J6: =I6 -> 338 | K6: =J6 -> 338
A7: Accounts and Notes Receivable | B7: 7822 | C7: 8404 | D7: 8680 | E7: 10163 | F7: 11456 | G7: =G59 -> 11221.934 | H7: =H59 -> 12157.485 | I7: =I59 -> 13174.049 | J7: =J59 -> 14278.907 | K7: =K59 -> 15480.018
A8: Inventories | B8: 3338 | C8: 4172 | D8: 4347 | E8: 5222 | F8: 5969 | G8: =G61 -> 5375.5778 | H8: =H61 -> 5886.1245 | I8: =I61 -> 6378.3006 | J8: =J61 -> 6913.2249 | K8: =K61 -> 7494.7504
A9: Prepaid expenses and other current assets | B9: 747 | C9: 874 | D9: 980 | E9: 806 | F9: 1075 | G9: =G63 -> 1096.2053 | H9: =H63 -> 1187.5938 | I9: =I63 -> 1286.8961 | J9: =J63 -> 1394.8232 | K9: =K63 -> 1512.1527
A10: Assets held for sale | B10: 0 | C10: 0 | D10: 1788 | E10: 0 | F10: 0 | G10: =F10 -> 0 | H10: =G10 -> 0 | I10: =H10 -> 0 | J10: =I10 -> 0 | K10: =J10 -> 0
A11: Total Current Assets | B11: =SUM(B5:B10) -> 17645 | C11: =SUM(C5:C10) -> 23001 | D11: =SUM(D5:D10) -> 21783 | E11: =SUM(E5:E10) -> 21539 | F11: =SUM(F5:F10) -> 24954 | G11: =SUM(G5:G10) -> 21163.027 | H11: =SUM(H5:H10) -> 24212.046 | I11: =SUM(I5:I10) -> 25319.835 | ... K11: =SUM(K5:K10) -> 29096.587
A13: Net Property, Plant & Equipment | B13: 19305 | C13: 21369 | D13: 22407 | E13: 24291 | F13: 24500 | G13: ='Fixed Assets Schedule'!H9 -> 29585.985 | H13: ='Fixed Assets Schedule'!I9 -> 30294.778 | I13: ='Fixed Assets Schedule'!J9 -> 32827.916 | J13: ='Fixed Assets Schedule'!K9 -> 35581.071 | K13: ='Fixed Assets Schedule'!L9 -> 38574.074
A14: Amortizable Intangible Assets, net | B14: 1433 | C14: 1703 | D14: 1538 | E14: 1277 | F14: 1232 | G14: ='Fixed Assets Schedule'!H28 -> 1198.5631 | H14: ='Fixed Assets Schedule'!I28 -> 1133.5042 | I14: ='Fixed Assets Schedule'!J28 -> 1071.9767 | J14: ='Fixed Assets Schedule'!K28 -> 1013.7891 | K14: ='Fixed Assets Schedule'!L28 -> 958.75985
A15: Goodwill | B15: 15501 | C15: 18757 | D15: 18381 | E15: 18202 | F15: 17997 | G15: =F15 -> 17997 | H15: =G15 -> 17997 | I15: =H15 -> 17997 | J15: =I15 -> 17997 | K15: =J15 -> 17997
A16: Other indefinite-lived intangible assets | B16: 14610 | C16: 17612 | D16: 17127 | E16: 14309 | F16: 14330 | G16: =F16 -> 14330 | H16: =G16 -> 14330 | I16: =H16 -> 14330 | J16: =I16 -> 14330 | K16: =J16 -> 14330
A17: Investments in Noncontrolled Affiliates | B17: 2683 | C17: 2792 | D17: 2350 | E17: 3073 | F17: 3038 | G17: =F17 -> 3038 | H17: =G17 -> 3038 | I17: =H17 -> 3038 | J17: =I17 -> 3038 | K17: =J17 -> 3038
A18: Deferred Income Taxes | B18: 4359 | C18: 4372 | D18: 4310 | E18: 4204 | F18: 4186 | G18: =F18 -> 4186 | H18: =G18 -> 4186 | I18: =H18 -> 4186 | J18: =I18 -> 4186 | K18: =J18 -> 4186
A19: Other Assets | B19: 3011 | C19: 3312 | D19: 4481 | E19: 5292 | F19: 5669 | G19: =F19 -> 5669 | H19: =G19 -> 5669 | I19: =H19 -> 5669 | J19: =I19 -> 5669 | K19: =J19 -> 5669
A20: Total Assets | B20: =SUM(B11,B13:B19) -> 78547 | C20: =SUM(C11,C13:C19) -> 92918 | D20: =SUM(D11,D13:D19) -> 92377 | E20: =SUM(E11,E13:E19) -> 92187 | F20: =SUM(F11,F13:F19) -> 95906 | G20: =SUM(G11,G13:G19) -> 97167.575 | H20: =SUM(H11,H13:H19) -> 100860.33 | I20: =SUM(I11,I13:I19) -> 104439.73 | ... K20: =SUM(K11,K13:K19) -> 113849.42
A22: LIABILITIES
A23: Short-term debt obligations | B23: 2920 | C23: 3780 | D23: 4308 | E23: 3414 | F23: 7613 | G23: ='Pepsico-Debt'!B50 -> 2867 | H23: ='Pepsico-Debt'!C50 -> 3193 | I23: ='Pepsico-Debt'!D50 -> 3246 | J23: ='Pepsico-Debt'!E50 -> 2523 | K23: ='Pepsico-Debt'!F50 -> 25302
A24: Accounts payable and other current liabilities | B24: 17541 | C24: 19592 | D24: 21159 | E24: 23371 | F24: 22005 | G24: =G67 -> 25837.618 | H24: =H67 -> 28291.552 | I24: =I67 -> 30657.188 | J24: =J67 -> 33228.292 | K24: =K67 -> 36023.384
A25: Liabilities held for sale | B25: 0 | C25: 0 | D25: 753 | E25: 0 | F25: 0 | G25: =F25 -> 0 | H25: =G25 -> 0 | I25: =H25 -> 0 | J25: =I25 -> 0 | K25: =J25 -> 0
A26: Total Current Liabilities | B26: =B23+B24+B25 -> 20461 | C26: =C23+C24+C25 -> 23372 | D26: =D23+D24+D25 -> 26220 | E26: =E23+E24+E25 -> 26785 | F26: =F23+F24+F25 -> 29618 | G26: =G23+G24+G25 -> 28704.618 | H26: =H23+H24+H25 -> 31484.552 | I26: =I23+I24+I25 -> 33903.188 | ... K26: =K23+K24+K25 -> 61325.384
A28: Long-Term Debt Obligations | B28: 29148 | C28: 40370 | D28: 36026 | E28: 35657 | F28: 36008 | G28: ='Pepsico-Debt'!B51 -> 35764 | H28: ='Pepsico-Debt'!C51 -> 32571 | I28: ='Pepsico-Debt'!D51 -> 29325 | J28: ='Pepsico-Debt'!E51 -> 26802 | K28: ='Pepsico-Debt'!F51 -> 1500
A29: Deferred Income Taxes | B29: 4091 | C29: 4284 | D29: 4826 | E29: 4133 | F29: 4113 | G29: =F29 -> 4113 | H29: =G29 -> 4113 | I29: =H29 -> 4113 | J29: =I29 -> 4113 | K29: =J29 -> 4113
A30: Other Liabilities | B30: 9979 | C30: 11340 | D30: 9154 | E30: 8339 | F30: 8342 | G30: =F30 -> 8342 | H30: =G30 -> 8342 | I30: =H30 -> 8342 | J30: =I30 -> 8342 | K30: =J30 -> 8342
A31: Total Liabilities | B31: =SUM(B26,B28:B30) -> 63679 | C31: =SUM(C26,C28:C30) -> 79366 | D31: =SUM(D26,D28:D30) -> 76226 | E31: =SUM(E26,E28:E30) -> 74914 | F31: =SUM(F26,F28:F30) -> 78081 | G31: =SUM(G26,G28:G30) -> 76923.618 | H31: =SUM(H26,H28:H30) -> 76510.552 | I31: =SUM(I26,I28:I30) -> 75683.188 | ... K31: =SUM(K26,K28:K30) -> 75280.384
A33: Common Stock | B33: 23 | C33: 23 | D33: 23 | E33: 23 | F33: 23 | G33: =F33 -> 23 | H33: =G33 -> 23 | I33: =H33 -> 23 | J33: =I33 -> 23 | K33: =J33 -> 23
A34: Capital in excess of par value | B34: 3886 | C34: 3910 | D34: 4001 | E34: 4134 | F34: 4082 | G34: =F34+'Pepsico-CFS'!B9 -> 4335.2735 | H34: =G34+'Pepsico-CFS'!C9 -> 4730.4277 | I34: =H34+'Pepsico-CFS'!D9 -> 5158.6233 | J34: =I34+'Pepsico-CFS'!E9 -> 5622.7301 | K34: =J34+'Pepsico-CFS'!F9 -> 6125.8765
A35: Retained Earnings | B35: 61946 | C35: 63443 | D35: 65165 | E35: 67800 | F35: 69135 | G35: =F35+'PepsiCo-IS'!G44+'Pepsico-CFS'!B24 -> 71249.297 | H35: =G35+'PepsiCo-IS'!I44+'Pepsico-CFS'!C24 -> 74880.116 | I35: =H35+'PepsiCo-IS'!J44+'Pepsico-CFS'!D24 -> 78773.073 | J35: =I35+'PepsiCo-IS'!K44+'Pepsico-CFS'!E24 -> 82954.466 | K35: =J35+'PepsiCo-IS'!L44+'Pepsico-CFS'!F24 -> 87427.983
A36: Accumulated other comprehensive loss | B36: -14300 | C36: -15476 | D36: -14898 | E36: -15302 | F36: -15780 | G36: =F36 -> -15780 | H36: =G36 -> -15780 | I36: =H36 -> -15780 | J36: =I36 -> -15780 | K36: =J36 -> -15780
A37: Repurchased common stock, in excess of par value | B37: -36769 | C37: -38446 | D37: -38248 | E37: -39506 | F37: -39775 | G37: =F37 -> -39775 | H37: =G37 -> -39775 | I37: =H37 -> -39775 | J37: =I37 -> -39775 | K37: =J37 -> -39775
A38: Total PepsiCo Common Shareholders’ Equity | B38: =SUM(B33:B37) -> 14786 | C38: =SUM(C33:C37) -> 13454 | D38: =SUM(D33:D37) -> 16043 | E38: =SUM(E33:E37) -> 17149 | F38: =SUM(F33:F37) -> 17685 | G38: =SUM(G33:G37) -> 20052.571 | H38: =SUM(H33:H37) -> 24078.544 | I38: =SUM(I33:I37) -> 28399.696 | ... K38: =SUM(K33:K37) -> 38021.859
A39: Noncontrolling interests | B39: 82 | C39: 98 | D39: 108 | E39: 124 | F39: 140 | G39: =F39+'PepsiCo-IS'!G42 -> 191.38588 | H39: =G39+'PepsiCo-IS'!I42 -> 271.23251 | I39: =H39+'PepsiCo-IS'!J42 -> 356.84392 | J39: =I39+'PepsiCo-IS'!K42 -> 448.79844 | K39: =J39+'PepsiCo-IS'!L42 -> 547.17716
A40: Total Equity | B40: =B38+B39 -> 14868 | C40: =C38+C39 -> 13552 | D40: =D38+D39 -> 16151 | E40: =E38+E39 -> 17273 | F40: =F38+F39 -> 17825 | G40: =G38+G39 -> 20243.957 | H40: =H38+H39 -> 24349.776 | I40: =I38+I39 -> 28756.54 | ... K40: =K38+K39 -> 38569.036
A42: Total Liabilities And Equity | B42: =B31+B40 -> 78547 | C42: =C31+C40 -> 92918 | D42: =D31+D40 -> 92377 | E42: =E31+E40 -> 92187 | F42: =F31+F40 -> 95906 | G42: =G31+G40 -> 97167.575 | H42: =H31+H40 -> 100860.33 | I42: =I31+I40 -> 104439.73 | ... K42: =K31+K40 -> 113849.42
A43: Check | B43: =B42-B20 -> 0 | C43: =C42-C20 -> 0 | D43: =D42-D20 -> 0 | E43: =E42-E20 -> 0 | F43: =F42-F20 -> 0 | G43: =G42-G20 -> 0 | H43: =H42-H20 -> 0 | I43: =I42-I20 -> 0 | ... K43: =K42-K20 -> 0
A44: Source | B44: 10K Dec'20, Pg 64 | D44: 10K Dec'22, Pg 66 | F44: 10Q June'23, Pg 8
A48: Accounts payable and other current liabilities | B48: =B24 -> 17541 | C48: =C24 -> 19592 | D48: =D24 -> 21159 | E48: =E24 -> 23371 | F48: =F24 -> 22005
...

Sheet Pepsico-CFS
A1: PepsiCo Inc.
A2: (in USD million except per Share Data)
A3: Cash Flow Statement | B3: 6 months | C3: 12 months | D3: 12 months | E3: 12 months | F3: 12 months
B4: Dec. 31, 2023 | C4: Dec. 31, 2024 | D4: Dec. 31, 2025 | E4: Dec. 31, 2026 | F4: Dec. 31, 2027
A6: Cash From Operating Activities
A7: Net Income | B7: ='PepsiCo-IS'!G38 -> 7135.4997 | C7: ='PepsiCo-IS'!I38 -> 11791.123 | D7: ='PepsiCo-IS'!J38 -> 12642.419 | E7: ='PepsiCo-IS'!K38 -> 13579.12 | F7: ='PepsiCo-IS'!L38 -> 14527.795
A8: Depreciation and amortization | B8: ='Fixed Assets Schedule'!H27+'Fixed Assets Schedule'!H8 -> 1655.908 | C8: ='Fixed Assets Schedule'!I27+'Fixed Assets Schedule'!I8 -> 3580.5256 | D8: ='Fixed Assets Schedule'!J27+'Fixed Assets Schedule'!J8 -> 3870.9446 | E8: ='Fixed Assets Schedule'!K27+'Fixed Assets Schedule'!K8 -> 4187.0864 | F8: ='Fixed Assets Schedule'!L27+'Fixed Assets Schedule'!L8 -> 4531.2419
A9: Share-based compensation expense | B9: ='PepsiCo-IS'!G63 -> 253.27346 | C9: ='PepsiCo-IS'!I63 -> 395.15426 | D9: ='PepsiCo-IS'!J63 -> 428.19561 | E9: ='PepsiCo-IS'!K63 -> 464.10678 | F9: ='PepsiCo-IS'!L63 -> 503.14644
A10: Change in assets and liabilities:
A11: Accounts and notes receivable | B11: =-('PepsiCo-BS'!G7-'PepsiCo-BS'!F7) -> 234.06643 | C11: =-('PepsiCo-BS'!H7-'PepsiCo-BS'!G7) -> -935.55109 | D11: =-('PepsiCo-BS'!I7-'PepsiCo-BS'!H7) -> -1016.5642 | E11: =-('PepsiCo-BS'!J7-'PepsiCo-BS'!I7) -> -1104.8582 | F11: =-('PepsiCo-BS'!K7-'PepsiCo-BS'!J7) -> -1201.1108
A12: Inventories | B12: =-('PepsiCo-BS'!G8-'PepsiCo-BS'!F8) -> 593.42225 | C12: =-('PepsiCo-BS'!H8-'PepsiCo-BS'!G8) -> -510.54676 | D12: =-('PepsiCo-BS'!I8-'PepsiCo-BS'!H8) -> -492.17613 | E12: =-('PepsiCo-BS'!J8-'PepsiCo-BS'!I8) -> -534.92423 | F12: =-('PepsiCo-BS'!K8-'PepsiCo-BS'!J8) -> -581.52553
A13: Prepaid expenses and other current assets | B13: =-('PepsiCo-BS'!G9-'PepsiCo-BS'!F9) -> -21.20529 | C13: =-('PepsiCo-BS'!H9-'PepsiCo-BS'!G9) -> -91.388533 | D13: =-('PepsiCo-BS'!I9-'PepsiCo-BS'!H9) -> -99.302236 | E13: =-('PepsiCo-BS'!J9-'PepsiCo-BS'!I9) -> -107.92716 | F13: =-('PepsiCo-BS'!K9-'PepsiCo-BS'!J9) -> -117.32951
A14: Accounts payable and other current liabilities | B14: ='PepsiCo-BS'!G24-'PepsiCo-BS'!F24 -> 3832.6183 | C14: ='PepsiCo-BS'!H24-'PepsiCo-BS'!G24 -> 2453.9339 | D14: ='PepsiCo-BS'!I24-'PepsiCo-BS'!H24 -> 2365.6357 | E14: ='PepsiCo-BS'!J24-'PepsiCo-BS'!I24 -> 2571.1038 | F14: ='PepsiCo-BS'!K24-'PepsiCo-BS'!J24 -> 2795.092
A16: Net Cash Provided by Operating Activities | B16: =SUM(B11:B14,B7:B9) -> 13683.583 | C16: =SUM(C11:C14,C7:C9) -> 16683.25 | D16: =SUM(D11:D14,D7:D9) -> 17699.153 | E16: =SUM(E11:E14,E7:E9) -> 19053.707 | F16: =SUM(F11:F14,F7:F9) -> 20457.31
A18: Cash From Investing Activities
A19: Capital Expenditure | B19: =-'Fixed Assets Schedule'!H6 -> -6708.4559 | C19: =-'Fixed Assets Schedule'!I6 -> -4224.2602 | D19: =-'Fixed Assets Schedule'!J6 -> -6342.5553 | E19: =-'Fixed Assets Schedule'!K6 -> -6882.0533 | F19: =-'Fixed Assets Schedule'!L6 -> -7469.2155
A21: Net Cash Used for Investing Activities | B21: =B19 -> -6708.4559 | C21: =C19 -> -4224.2602 | D21: =D19 -> -6342.5553 | E21: =E19 -> -6882.0533 | F21: =F19 -> -7469.2155
A23: Cash From Financing Activities
A24: Cash dividends paid | B24: =-('PepsiCo-IS'!G67*'PepsiCo-IS'!G46) -> -4969.8164 | C24: =-('PepsiCo-IS'!I67*'PepsiCo-IS'!I46) -> -8080.4578 | D24: =-('PepsiCo-IS'!J67*'PepsiCo-IS'!J46) -> -8663.8513 | E24: =-('PepsiCo-IS'!K67*'PepsiCo-IS'!K46) -> -9305.772 | F24: =-('PepsiCo-IS'!L67*'PepsiCo-IS'!L46) -> -9955.8996
A25: Cash before Raising (Repayment) of Debt | B25: =B16+B21+B24 -> 2005.3106 | C25: =C16+C21+C24 -> 4378.5324 | D25: =D16+D21+D24 -> 2692.7462 | E25: =E16+E21+E24 -> 2865.8815 | F25: =F16+F21+F24 -> 3032.1948
A27: Debt Raised | B27: ='Pepsico-Debt'!B41 -> 0 | C27: ='Pepsico-Debt'!C41 -> 0 | D27: ='Pepsico-Debt'!D41 -> 0 | E27: ='Pepsico-Debt'!E41 -> 0 | F27: ='Pepsico-Debt'!F41 -> 0
A28: Debt Repaid | B28: ='Pepsico-Debt'!B42+'Pepsico-Debt'!B9 -> -4990 | C28: ='Pepsico-Debt'!C42+'Pepsico-Debt'!C9 -> -2867 | D28: ='Pepsico-Debt'!D42+'Pepsico-Debt'!D9 -> -3193 | E28: ='Pepsico-Debt'!E42+'Pepsico-Debt'!E9 -> -3246 | F28: ='Pepsico-Debt'!F42+'Pepsico-Debt'!F9 -> -2523
A31: Net Cash Provided by/(Used for) Financing Activities | B31: =B24+B27+B28 -> -9959.8164 | C31: =C24+C27+C28 -> -10947.458 | D31: =D24+D27+D28 -> -11856.851 | E31: =E24+E27+E28 -> -12551.772 | F31: =F24+F27+F28 -> -12478.9
A33: Net Increase/(Decrease) in Cash and Cash Equivalents | B33: =B31+B21+B16 -> -2984.6894 | C33: =C31+C21+C16 -> 1511.5324 | D33: =D31+D21+D16 -> -500.25383 | E33: =E31+E21+E16 -> -380.11851 | F33: =F31+F21+F16 -> 509.19482
A34: Cash and Cash Equivalents, Beginning of Year | B34: ='PepsiCo-BS'!F5 -> 6116 | C34: ='PepsiCo-BS'!G5 -> 3131.3106 | D34: ='PepsiCo-BS'!H5 -> 4642.843 | E34: ='PepsiCo-BS'!I5 -> 4142.5892 | F34: ='PepsiCo-BS'!J5 -> 3762.4707
A35: Cash and Cash Equivalents, End of Period | B35: =B34+B33 -> 3131.3106 | C35: =C34+C33 -> 4642.843 | D35: =D34+D33 -> 4142.5892 | E35: =E34+E33 -> 3762.4707 | F35: =F34+F33 -> 4271.6655
A37: Source: Calculations

Sheet Pepsico-Debt
A1: PepsiCo Inc.
A2: (in USD million except per Share Data)
A3: Debt Schedule | B3: 6 months | C3: 12 months | D3: 12 months | E3: 12 months | F3: 12 months
B4: Dec. 31, 2023 | C4: Dec. 31, 2024 | D4: Dec. 31, 2025 | E4: Dec. 31, 2026 | F4: Dec. 31, 2027
A6: Cash Before Debt | B6: ='Pepsico-CFS'!B25 -> 2005.3106 | C6: ='Pepsico-CFS'!C25 -> 4378.5324 | D6: ='Pepsico-CFS'!D25 -> 2692.7462 | E6: ='Pepsico-CFS'!E25 -> 2865.8815 | F6: ='Pepsico-CFS'!F25 -> 3032.1948
A7: Add: Opening Cash Balance | B7: ='PepsiCo-BS'!F5 -> 6116 | C7: ='PepsiCo-BS'!G5 -> 3131.3106 | D7: ='PepsiCo-BS'!H5 -> 4642.843 | E7: ='PepsiCo-BS'!I5 -> 4142.5892 | F7: ='PepsiCo-BS'!J5 -> 3762.4707
A8: Cash Available for Debt | B8: =B6+B7 -> 8121.3106 | C8: =C6+C7 -> 7509.843 | D8: =D6+D7 -> 7335.5892 | E8: =E6+E7 -> 7008.4707 | F8: =F6+F7 -> 6794.6655
A9: Less: Mandatory Debt Repayments | B9: =-(I17+I23) -> -822 | C9: =-I18 -> -2867 | D9: =-(I19) -> -3193 | E9: =-(I20+I24+I25) -> -3246 | F9: =-(I21) -> -2523 | G9: =-(I22+I26) -> -25302
A10: Cash Available for Discretionery Sweep | B10: =B8+B9 -> 7299.3106 | C10: =C8+C9 -> 4642.843 | D10: =D8+D9 -> 4142.5892 | E10: =E8+E9 -> 3762.4707 | F10: =F8+F9 -> 4271.6655
A11: Source: Calculations
M13: Interest Expenses
A14: Mandatory Debt | F14: Balance As on 31 Dec 2022 | I14: Net Balance As on 30 June 2023 | M14: =B3 -> 6 months | N14: =C3 -> 12 months | O14: =D3 -> 12 months | P14: =E3 -> 12 months | Q14: =F3 -> 12 months
B15: Repayment Date | C15: Interest Rate | E15: Average Rate | G15: Raised | H15: Repaid | L15: 45094 | M15: 45291 | N15: 45657 | O15: 46022 | P15: 46387 | Q15: 46752
A16: 2022 Notes | B16: 44926 | C16: 0.024 | D16: 0.024 | E16: =AVERAGE(C16:D16) -> 0.024 | F16: 0 | I16: =F16+G16-H16 -> 0 | J16: 10K Dec 2022, Pg 97 | M16: =IF($B16>L$15,$I16*$E16*(MIN($B16-L$15,M$15-L$15))/365,0) -> 0 | N16: =IF($B16>M$15,$I16*$E16*(MIN($B16-M$15,N$15-M$15))/365,0) -> 0 | O16: =IF($B16>N$15,$I16*$E16*(MIN($B16-N$15,O$15-N$15))/365,0) -> 0 | P16: =IF($B16>O$15,$I16*$E16*(MIN($B16-O$15,P$15-O$15))/365,0) -> 0 | Q16: =IF($B16>P$15,$I16*$E16*(MIN($B16-P$15,Q$15-P$15))/365,0) -> 0
A17: 2023 Notes | B17: 45291 | C17: 0.017 | D17: 0.015 | E17: =AVERAGE(C17:D17) -> 0.016 | F17: 3094 | H17: 2300 | I17: =F17+G17-H17 -> 794 | J17: 10K Dec 2022, Pg 97 | L17: =I17*E17*(B17-L15)/365 -> 6.8566795 | M17: =IF($B17>L$15,$I17*$E17*(MIN($B17-L$15,M$15-L$15))/365,0) -> 6.8566795 | N17: =IF($B17>M$15,$I17*$E17*(MIN($B17-M$15,N$15-M$15))/365,0) -> 0 | O17: =IF($B17>N$15,$I17*$E17*(MIN($B17-N$15,O$15-N$15))/365,0) -> 0 | P17: =IF($B17>O$15,$I17*$E17*(MIN($B17-O$15,P$15-O$15))/365,0) -> 0 | Q17: =IF($B17>P$15,$I17*$E17*(MIN($B17-P$15,Q$15-P$15))/365,0) -> 0
A18: 2024 Notes | B18: 45657 | C18: 0.022 | D18: 0.021 | E18: =AVERAGE(C18:D18) -> 0.0215 | F18: 2867 | I18: =F18+G18-H18 -> 2867 | J18: 10K Dec 2022, Pg 97 | M18: =IF($B18>L$15,$I18*$E18*(MIN($B18-L$15,M$15-L$15))/365,0) -> 33.268982 | N18: =IF($B18>M$15,$I18*$E18*(MIN($B18-M$15,N$15-M$15))/365,0) -> 61.809378 | O18: =IF($B18>N$15,$I18*$E18*(MIN($B18-N$15,O$15-N$15))/365,0) -> 0 | P18: =IF($B18>O$15,$I18*$E18*(MIN($B18-O$15,P$15-O$15))/365,0) -> 0 | Q18: =IF($B18>P$15,$I18*$E18*(MIN($B18-P$15,Q$15-P$15))/365,0) -> 0
A19: 2025 Notes | B19: 46022 | C19: 0.027 | D19: 0.027 | E19: =AVERAGE(C19:D19) -> 0.027 | F19: 3193 | I19: =F19+G19-H19 -> 3193 | J19: 10K Dec 2022, Pg 97 | M19: =IF($B19>L$15,$I19*$E19*(MIN($B19-L$15,M$15-L$15))/365,0) -> 46.530321 | N19: =IF($B19>M$15,$I19*$E19*(MIN($B19-M$15,N$15-M$15))/365,0) -> 86.447195 | O19: =IF($B19>N$15,$I19*$E19*(MIN($B19-N$15,O$15-N$15))/365,0) -> 86.211 | P19: =IF($B19>O$15,$I19*$E19*(MIN($B19-O$15,P$15-O$15))/365,0) -> 0 | Q19: =IF($B19>P$15,$I19*$E19*(MIN($B19-P$15,Q$15-P$15))/365,0) -> 0
A20: 2026 Notes | B20: 46387 | C20: 0.031 | D20: 0.032 | E20: =AVERAGE(C20:D20) -> 0.0315 | F20: 2396 | I20: =F20+G20-H20 -> 2396 | J20: 10K Dec 2022, Pg 97 | M20: =IF($B20>L$15,$I20*$E20*(MIN($B20-L$15,M$15-L$15))/365,0) -> 40.735282 | N20: =IF($B20>M$15,$I20*$E20*(MIN($B20-M$15,N$15-M$15))/365,0) -> 75.680778 | O20: =IF($B20>N$15,$I20*$E20*(MIN($B20-N$15,O$15-N$15))/365,0) -> 75.474 | P20: =IF($B20>O$15,$I20*$E20*(MIN($B20-O$15,P$15-O$15))/365,0) -> 75.474 | Q20: =IF($B20>P$15,$I20*$E20*(MIN($B20-P$15,Q$15-P$15))/365,0) -> 0
A21: 2027 Notes | B21: 46752 | C21: 0.025 | D21: 0.024 | E21: =AVERAGE(C21:D21) -> 0.0245 | F21: 2523 | I21: =F21+G21-H21 -> 2523 | J21: 10K Dec 2022, Pg 97 | M21: =IF($B21>L$15,$I21*$E21*(MIN($B21-L$15,M$15-L$15))/365,0) -> 33.362355 | N21: =IF($B21>M$15,$I21*$E21*(MIN($B21-M$15,N$15-M$15))/365,0) -> 61.982852 | O21: =IF($B21>N$15,$I21*$E21*(MIN($B21-N$15,O$15-N$15))/365,0) -> 61.8135 | P21: =IF($B21>O$15,$I21*$E21*(MIN($B21-O$15,P$15-O$15))/365,0) -> 61.8135 | Q21: =IF($B21>P$15,$I21*$E21*(MIN($B21-P$15,Q$15-P$15))/365,0) -> 61.8135
A22: 2028-2060 Notes | B22: 47118 | C22: 0.028 | D22: 0.026 | E22: =AVERAGE(C22:D22) -> 0.027 | F22: 24652 | I22: =F22+G22-H22 -> 24652 | J22: 10K Dec 2022, Pg 97 | M22: =IF($B22>L$15,$I22*$E22*(MIN($B22-L$15,M$15-L$15))/365,0) -> 359.2438 | N22: =IF($B22>M$15,$I22*$E22*(MIN($B22-M$15,N$15-M$15))/365,0) -> 667.42757 | O22: =IF($B22>N$15,$I22*$E22*(MIN($B22-N$15,O$15-N$15))/365,0) -> 665.604 | P22: =IF($B22>O$15,$I22*$E22*(MIN($B22-O$15,P$15-O$15))/365,0) -> 665.604 | Q22: =IF($B22>P$15,$I22*$E22*(MIN($B22-P$15,Q$15-P$15))/365,0) -> 665.604
A23: 2022-2028 Notes | B23: 45291 | C23: 0.013 | D23: 0.013 | E23: =AVERAGE(C23:D23) -> 0.013 | F23: 28 | I23: =F23+G23-H23 -> 28 | J23: 10K Dec 2022, Pg 97 | M23: =IF($B23>L$15,$I23*$E23*(MIN($B23-L$15,M$15-L$15))/365,0) -> 0.19646027 | N23: =IF($B23>M$15,$I23*$E23*(MIN($B23-M$15,N$15-M$15))/365,0) -> 0 | O23: =IF($B23>N$15,$I23*$E23*(MIN($B23-N$15,O$15-N$15))/365,0) -> 0 | P23: =IF($B23>O$15,$I23*$E23*(MIN($B23-O$15,P$15-O$15))/365,0) -> 0 | Q23: =IF($B23>P$15,$I23*$E23*(MIN($B23-P$15,Q$15-P$15))/365,0) -> 0
